===============================================
Starting Django Reset and Seed Process (PostgreSQL)
Mon, Jun  2, 2025  8:19:23 PM
===============================================
Step 1: Dropping and creating PostgreSQL database...
reset_and_seed_postgresql.sh: line 28: sudo: command not found
reset_and_seed_postgresql.sh: line 29: sudo: command not found
✓ Database reset successfully
Step 2: Removing ALL migration files...
Step 3: Removing existing SQLite databases...
Step 4: Ensuring migrations directory...
Step 5: Creating new migrations...
D:\PramLearn\.venv\Lib\site-packages\rest_framework_simplejwt\__init__.py:1: UserWarning: pkg_resources is deprecated as an API. See https://setuptools.pypa.io/en/latest/pkg_resources.html. The pkg_resources package is slated for removal as early as 2025-11-30. Refrain from using this package or pin to Setuptools<81.
  from pkg_resources import DistributionNotFound, get_distribution
Traceback (most recent call last):
  File "D:\PramLearn\.venv\Lib\site-packages\django\db\backends\base\base.py", line 275, in ensure_connection
    self.connect()
  File "D:\PramLearn\.venv\Lib\site-packages\django\utils\asyncio.py", line 26, in inner
    return func(*args, **kwargs)
           ^^^^^^^^^^^^^^^^^^^^^
  File "D:\PramLearn\.venv\Lib\site-packages\django\db\backends\base\base.py", line 256, in connect
    self.connection = self.get_new_connection(conn_params)
                      ^^^^^^^^^^^^^^^^^^^^^^^^^^^^^^^^^^^^
  File "D:\PramLearn\.venv\Lib\site-packages\django\utils\asyncio.py", line 26, in inner
    return func(*args, **kwargs)
           ^^^^^^^^^^^^^^^^^^^^^
  File "D:\PramLearn\.venv\Lib\site-packages\django\db\backends\postgresql\base.py", line 277, in get_new_connection
    connection = self.Database.connect(**conn_params)
                 ^^^^^^^^^^^^^^^^^^^^^^^^^^^^^^^^^^^^
  File "D:\PramLearn\.venv\Lib\site-packages\psycopg2\__init__.py", line 121, in connect
    dsn = _ext.make_dsn(dsn, **kwargs)
          ^^^^^^^^^^^^^^^^^^^^^^^^^^^^
  File "D:\PramLearn\.venv\Lib\site-packages\psycopg2\extensions.py", line 167, in make_dsn
    parse_dsn(dsn)
psycopg2.ProgrammingError: invalid dsn: invalid connection option "charset"


The above exception was the direct cause of the following exception:

Traceback (most recent call last):
  File "D:\PramLearn\backendpramlearn\manage.py", line 22, in <module>
    main()
  File "D:\PramLearn\backendpramlearn\manage.py", line 18, in main
    execute_from_command_line(sys.argv)
  File "D:\PramLearn\.venv\Lib\site-packages\django\core\management\__init__.py", line 442, in execute_from_command_line
    utility.execute()
  File "D:\PramLearn\.venv\Lib\site-packages\django\core\management\__init__.py", line 436, in execute
    self.fetch_command(subcommand).run_from_argv(self.argv)
  File "D:\PramLearn\.venv\Lib\site-packages\django\core\management\base.py", line 413, in run_from_argv
    self.execute(*args, **cmd_options)
  File "D:\PramLearn\.venv\Lib\site-packages\django\core\management\base.py", line 459, in execute
    output = self.handle(*args, **options)
             ^^^^^^^^^^^^^^^^^^^^^^^^^^^^^
  File "D:\PramLearn\.venv\Lib\site-packages\django\core\management\base.py", line 107, in wrapper
    res = handle_func(*args, **kwargs)
          ^^^^^^^^^^^^^^^^^^^^^^^^^^^^
  File "D:\PramLearn\.venv\Lib\site-packages\django\core\management\commands\makemigrations.py", line 158, in handle
    loader.check_consistent_history(connection)
  File "D:\PramLearn\.venv\Lib\site-packages\django\db\migrations\loader.py", line 313, in check_consistent_history
    applied = recorder.applied_migrations()
              ^^^^^^^^^^^^^^^^^^^^^^^^^^^^^
  File "D:\PramLearn\.venv\Lib\site-packages\django\db\migrations\recorder.py", line 89, in applied_migrations
    if self.has_table():
       ^^^^^^^^^^^^^^^^
  File "D:\PramLearn\.venv\Lib\site-packages\django\db\migrations\recorder.py", line 63, in has_table
    with self.connection.cursor() as cursor:
         ^^^^^^^^^^^^^^^^^^^^^^^^
  File "D:\PramLearn\.venv\Lib\site-packages\django\utils\asyncio.py", line 26, in inner
    return func(*args, **kwargs)
           ^^^^^^^^^^^^^^^^^^^^^
  File "D:\PramLearn\.venv\Lib\site-packages\django\db\backends\base\base.py", line 316, in cursor
    return self._cursor()
           ^^^^^^^^^^^^^^
  File "D:\PramLearn\.venv\Lib\site-packages\django\db\backends\base\base.py", line 292, in _cursor
    self.ensure_connection()
  File "D:\PramLearn\.venv\Lib\site-packages\django\utils\asyncio.py", line 26, in inner
    return func(*args, **kwargs)
           ^^^^^^^^^^^^^^^^^^^^^
  File "D:\PramLearn\.venv\Lib\site-packages\django\db\backends\base\base.py", line 274, in ensure_connection
    with self.wrap_database_errors:
         ^^^^^^^^^^^^^^^^^^^^^^^^^
  File "D:\PramLearn\.venv\Lib\site-packages\django\db\utils.py", line 91, in __exit__
    raise dj_exc_value.with_traceback(traceback) from exc_value
  File "D:\PramLearn\.venv\Lib\site-packages\django\db\backends\base\base.py", line 275, in ensure_connection
    self.connect()
  File "D:\PramLearn\.venv\Lib\site-packages\django\utils\asyncio.py", line 26, in inner
    return func(*args, **kwargs)
           ^^^^^^^^^^^^^^^^^^^^^
  File "D:\PramLearn\.venv\Lib\site-packages\django\db\backends\base\base.py", line 256, in connect
    self.connection = self.get_new_connection(conn_params)
                      ^^^^^^^^^^^^^^^^^^^^^^^^^^^^^^^^^^^^
  File "D:\PramLearn\.venv\Lib\site-packages\django\utils\asyncio.py", line 26, in inner
    return func(*args, **kwargs)
           ^^^^^^^^^^^^^^^^^^^^^
  File "D:\PramLearn\.venv\Lib\site-packages\django\db\backends\postgresql\base.py", line 277, in get_new_connection
    connection = self.Database.connect(**conn_params)
                 ^^^^^^^^^^^^^^^^^^^^^^^^^^^^^^^^^^^^
  File "D:\PramLearn\.venv\Lib\site-packages\psycopg2\__init__.py", line 121, in connect
    dsn = _ext.make_dsn(dsn, **kwargs)
          ^^^^^^^^^^^^^^^^^^^^^^^^^^^^
  File "D:\PramLearn\.venv\Lib\site-packages\psycopg2\extensions.py", line 167, in make_dsn
    parse_dsn(dsn)
django.db.utils.ProgrammingError: invalid dsn: invalid connection option "charset"

✓ Migrations created successfully
Step 6: Applying migrations...
D:\PramLearn\.venv\Lib\site-packages\rest_framework_simplejwt\__init__.py:1: UserWarning: pkg_resources is deprecated as an API. See https://setuptools.pypa.io/en/latest/pkg_resources.html. The pkg_resources package is slated for removal as early as 2025-11-30. Refrain from using this package or pin to Setuptools<81.
  from pkg_resources import DistributionNotFound, get_distribution
Traceback (most recent call last):
  File "D:\PramLearn\.venv\Lib\site-packages\django\db\backends\base\base.py", line 275, in ensure_connection
    self.connect()
  File "D:\PramLearn\.venv\Lib\site-packages\django\utils\asyncio.py", line 26, in inner
    return func(*args, **kwargs)
           ^^^^^^^^^^^^^^^^^^^^^
  File "D:\PramLearn\.venv\Lib\site-packages\django\db\backends\base\base.py", line 256, in connect
    self.connection = self.get_new_connection(conn_params)
                      ^^^^^^^^^^^^^^^^^^^^^^^^^^^^^^^^^^^^
  File "D:\PramLearn\.venv\Lib\site-packages\django\utils\asyncio.py", line 26, in inner
    return func(*args, **kwargs)
           ^^^^^^^^^^^^^^^^^^^^^
  File "D:\PramLearn\.venv\Lib\site-packages\django\db\backends\postgresql\base.py", line 277, in get_new_connection
    connection = self.Database.connect(**conn_params)
                 ^^^^^^^^^^^^^^^^^^^^^^^^^^^^^^^^^^^^
  File "D:\PramLearn\.venv\Lib\site-packages\psycopg2\__init__.py", line 121, in connect
    dsn = _ext.make_dsn(dsn, **kwargs)
          ^^^^^^^^^^^^^^^^^^^^^^^^^^^^
  File "D:\PramLearn\.venv\Lib\site-packages\psycopg2\extensions.py", line 167, in make_dsn
    parse_dsn(dsn)
psycopg2.ProgrammingError: invalid dsn: invalid connection option "charset"


The above exception was the direct cause of the following exception:

Traceback (most recent call last):
  File "D:\PramLearn\backendpramlearn\manage.py", line 22, in <module>
    main()
  File "D:\PramLearn\backendpramlearn\manage.py", line 18, in main
    execute_from_command_line(sys.argv)
  File "D:\PramLearn\.venv\Lib\site-packages\django\core\management\__init__.py", line 442, in execute_from_command_line
    utility.execute()
  File "D:\PramLearn\.venv\Lib\site-packages\django\core\management\__init__.py", line 436, in execute
    self.fetch_command(subcommand).run_from_argv(self.argv)
  File "D:\PramLearn\.venv\Lib\site-packages\django\core\management\base.py", line 413, in run_from_argv
    self.execute(*args, **cmd_options)
  File "D:\PramLearn\.venv\Lib\site-packages\django\core\management\base.py", line 459, in execute
    output = self.handle(*args, **options)
             ^^^^^^^^^^^^^^^^^^^^^^^^^^^^^
  File "D:\PramLearn\.venv\Lib\site-packages\django\core\management\base.py", line 107, in wrapper
    res = handle_func(*args, **kwargs)
          ^^^^^^^^^^^^^^^^^^^^^^^^^^^^
  File "D:\PramLearn\.venv\Lib\site-packages\django\core\management\commands\migrate.py", line 100, in handle
    self.check(databases=[database])
  File "D:\PramLearn\.venv\Lib\site-packages\django\core\management\base.py", line 486, in check
    all_issues = checks.run_checks(
                 ^^^^^^^^^^^^^^^^^^
  File "D:\PramLearn\.venv\Lib\site-packages\django\core\checks\registry.py", line 88, in run_checks
    new_errors = check(app_configs=app_configs, databases=databases)
                 ^^^^^^^^^^^^^^^^^^^^^^^^^^^^^^^^^^^^^^^^^^^^^^^^^^^
  File "D:\PramLearn\.venv\Lib\site-packages\django\core\checks\model_checks.py", line 36, in check_all_models
    errors.extend(model.check(**kwargs))
                  ^^^^^^^^^^^^^^^^^^^^^
  File "D:\PramLearn\.venv\Lib\site-packages\django\db\models\base.py", line 1622, in check
    *cls._check_constraints(databases),
     ^^^^^^^^^^^^^^^^^^^^^^^^^^^^^^^^^
  File "D:\PramLearn\.venv\Lib\site-packages\django\db\models\base.py", line 2472, in _check_constraints
    connection.features.supports_nulls_distinct_unique_constraints
  File "D:\PramLearn\.venv\Lib\site-packages\django\utils\functional.py", line 47, in __get__
    res = instance.__dict__[self.name] = self.func(instance)
                                         ^^^^^^^^^^^^^^^^^^^
  File "D:\PramLearn\.venv\Lib\site-packages\django\db\backends\postgresql\features.py", line 141, in is_postgresql_15
    return self.connection.pg_version >= 150000
           ^^^^^^^^^^^^^^^^^^^^^^^^^^
  File "D:\PramLearn\.venv\Lib\site-packages\django\utils\functional.py", line 47, in __get__
    res = instance.__dict__[self.name] = self.func(instance)
                                         ^^^^^^^^^^^^^^^^^^^
  File "D:\PramLearn\.venv\Lib\site-packages\django\db\backends\postgresql\base.py", line 438, in pg_version
    with self.temporary_connection():
         ^^^^^^^^^^^^^^^^^^^^^^^^^^^
  File "C:\Users\rehaa\AppData\Local\Programs\Python\Python312\Lib\contextlib.py", line 137, in __enter__
    return next(self.gen)
           ^^^^^^^^^^^^^^
  File "D:\PramLearn\.venv\Lib\site-packages\django\db\backends\base\base.py", line 691, in temporary_connection
    with self.cursor() as cursor:
         ^^^^^^^^^^^^^
  File "D:\PramLearn\.venv\Lib\site-packages\django\utils\asyncio.py", line 26, in inner
    return func(*args, **kwargs)
           ^^^^^^^^^^^^^^^^^^^^^
  File "D:\PramLearn\.venv\Lib\site-packages\django\db\backends\base\base.py", line 316, in cursor
    return self._cursor()
           ^^^^^^^^^^^^^^
  File "D:\PramLearn\.venv\Lib\site-packages\django\db\backends\base\base.py", line 292, in _cursor
    self.ensure_connection()
  File "D:\PramLearn\.venv\Lib\site-packages\django\utils\asyncio.py", line 26, in inner
    return func(*args, **kwargs)
           ^^^^^^^^^^^^^^^^^^^^^
  File "D:\PramLearn\.venv\Lib\site-packages\django\db\backends\base\base.py", line 274, in ensure_connection
    with self.wrap_database_errors:
         ^^^^^^^^^^^^^^^^^^^^^^^^^
  File "D:\PramLearn\.venv\Lib\site-packages\django\db\utils.py", line 91, in __exit__
    raise dj_exc_value.with_traceback(traceback) from exc_value
  File "D:\PramLearn\.venv\Lib\site-packages\django\db\backends\base\base.py", line 275, in ensure_connection
    self.connect()
  File "D:\PramLearn\.venv\Lib\site-packages\django\utils\asyncio.py", line 26, in inner
    return func(*args, **kwargs)
           ^^^^^^^^^^^^^^^^^^^^^
  File "D:\PramLearn\.venv\Lib\site-packages\django\db\backends\base\base.py", line 256, in connect
    self.connection = self.get_new_connection(conn_params)
                      ^^^^^^^^^^^^^^^^^^^^^^^^^^^^^^^^^^^^
  File "D:\PramLearn\.venv\Lib\site-packages\django\utils\asyncio.py", line 26, in inner
    return func(*args, **kwargs)
           ^^^^^^^^^^^^^^^^^^^^^
  File "D:\PramLearn\.venv\Lib\site-packages\django\db\backends\postgresql\base.py", line 277, in get_new_connection
    connection = self.Database.connect(**conn_params)
                 ^^^^^^^^^^^^^^^^^^^^^^^^^^^^^^^^^^^^
  File "D:\PramLearn\.venv\Lib\site-packages\psycopg2\__init__.py", line 121, in connect
    dsn = _ext.make_dsn(dsn, **kwargs)
          ^^^^^^^^^^^^^^^^^^^^^^^^^^^^
  File "D:\PramLearn\.venv\Lib\site-packages\psycopg2\extensions.py", line 167, in make_dsn
    parse_dsn(dsn)
django.db.utils.ProgrammingError: invalid dsn: invalid connection option "charset"

✓ Migrations applied successfully
Step 7: Verifying database tables...
D:\PramLearn\.venv\Lib\site-packages\rest_framework_simplejwt\__init__.py:1: UserWarning: pkg_resources is deprecated as an API. See https://setuptools.pypa.io/en/latest/pkg_resources.html. The pkg_resources package is slated for removal as early as 2025-11-30. Refrain from using this package or pin to Setuptools<81.
  from pkg_resources import DistributionNotFound, get_distribution
Traceback (most recent call last):
  File "D:\PramLearn\.venv\Lib\site-packages\django\db\backends\base\base.py", line 275, in ensure_connection
    self.connect()
  File "D:\PramLearn\.venv\Lib\site-packages\django\utils\asyncio.py", line 26, in inner
    return func(*args, **kwargs)
           ^^^^^^^^^^^^^^^^^^^^^
  File "D:\PramLearn\.venv\Lib\site-packages\django\db\backends\base\base.py", line 256, in connect
    self.connection = self.get_new_connection(conn_params)
                      ^^^^^^^^^^^^^^^^^^^^^^^^^^^^^^^^^^^^
  File "D:\PramLearn\.venv\Lib\site-packages\django\utils\asyncio.py", line 26, in inner
    return func(*args, **kwargs)
           ^^^^^^^^^^^^^^^^^^^^^
  File "D:\PramLearn\.venv\Lib\site-packages\django\db\backends\postgresql\base.py", line 277, in get_new_connection
    connection = self.Database.connect(**conn_params)
                 ^^^^^^^^^^^^^^^^^^^^^^^^^^^^^^^^^^^^
  File "D:\PramLearn\.venv\Lib\site-packages\psycopg2\__init__.py", line 121, in connect
    dsn = _ext.make_dsn(dsn, **kwargs)
          ^^^^^^^^^^^^^^^^^^^^^^^^^^^^
  File "D:\PramLearn\.venv\Lib\site-packages\psycopg2\extensions.py", line 167, in make_dsn
    parse_dsn(dsn)
psycopg2.ProgrammingError: invalid dsn: invalid connection option "charset"


The above exception was the direct cause of the following exception:

Traceback (most recent call last):
  File "<string>", line 7, in <module>
  File "D:\PramLearn\.venv\Lib\site-packages\django\utils\asyncio.py", line 26, in inner
    return func(*args, **kwargs)
           ^^^^^^^^^^^^^^^^^^^^^
  File "D:\PramLearn\.venv\Lib\site-packages\django\db\backends\base\base.py", line 316, in cursor
    return self._cursor()
           ^^^^^^^^^^^^^^
  File "D:\PramLearn\.venv\Lib\site-packages\django\db\backends\base\base.py", line 292, in _cursor
    self.ensure_connection()
  File "D:\PramLearn\.venv\Lib\site-packages\django\utils\asyncio.py", line 26, in inner
    return func(*args, **kwargs)
           ^^^^^^^^^^^^^^^^^^^^^
  File "D:\PramLearn\.venv\Lib\site-packages\django\db\backends\base\base.py", line 274, in ensure_connection
    with self.wrap_database_errors:
         ^^^^^^^^^^^^^^^^^^^^^^^^^
  File "D:\PramLearn\.venv\Lib\site-packages\django\db\utils.py", line 91, in __exit__
    raise dj_exc_value.with_traceback(traceback) from exc_value
  File "D:\PramLearn\.venv\Lib\site-packages\django\db\backends\base\base.py", line 275, in ensure_connection
    self.connect()
  File "D:\PramLearn\.venv\Lib\site-packages\django\utils\asyncio.py", line 26, in inner
    return func(*args, **kwargs)
           ^^^^^^^^^^^^^^^^^^^^^
  File "D:\PramLearn\.venv\Lib\site-packages\django\db\backends\base\base.py", line 256, in connect
    self.connection = self.get_new_connection(conn_params)
                      ^^^^^^^^^^^^^^^^^^^^^^^^^^^^^^^^^^^^
  File "D:\PramLearn\.venv\Lib\site-packages\django\utils\asyncio.py", line 26, in inner
    return func(*args, **kwargs)
           ^^^^^^^^^^^^^^^^^^^^^
  File "D:\PramLearn\.venv\Lib\site-packages\django\db\backends\postgresql\base.py", line 277, in get_new_connection
    connection = self.Database.connect(**conn_params)
                 ^^^^^^^^^^^^^^^^^^^^^^^^^^^^^^^^^^^^
  File "D:\PramLearn\.venv\Lib\site-packages\psycopg2\__init__.py", line 121, in connect
    dsn = _ext.make_dsn(dsn, **kwargs)
          ^^^^^^^^^^^^^^^^^^^^^^^^^^^^
  File "D:\PramLearn\.venv\Lib\site-packages\psycopg2\extensions.py", line 167, in make_dsn
    parse_dsn(dsn)
django.db.utils.ProgrammingError: invalid dsn: invalid connection option "charset"

Step 8: Removing existing initial_data.json...
Step 9: Generating initial_data.json...
D:\PramLearn\.venv\Lib\site-packages\rest_framework_simplejwt\__init__.py:1: UserWarning: pkg_resources is deprecated as an API. See https://setuptools.pypa.io/en/latest/pkg_resources.html. The pkg_resources package is slated for removal as early as 2025-11-30. Refrain from using this package or pin to Setuptools<81.
  from pkg_resources import DistributionNotFound, get_distribution
Generating basic initial data...
- Generating roles...
- Generating users...
- Generating classes...
- Generating subjects...
- Generating subject classes...
- Generating class students...
- Writing to file...
Generated 158 records successfully!
- Roles: 3
- Users: 62
- Classes: 8
- Subjects: 20
- Subject Classes: 15
- Class Students: 50

✓ Basic data generated successfully!
✓ Materials, Files, Assignments, Quizzes can be created manually via the application
✓ Initial data generated successfully
Step 10: Loading seed data...
D:\PramLearn\.venv\Lib\site-packages\rest_framework_simplejwt\__init__.py:1: UserWarning: pkg_resources is deprecated as an API. See https://setuptools.pypa.io/en/latest/pkg_resources.html. The pkg_resources package is slated for removal as early as 2025-11-30. Refrain from using this package or pin to Setuptools<81.
  from pkg_resources import DistributionNotFound, get_distribution
Traceback (most recent call last):
  File "D:\PramLearn\.venv\Lib\site-packages\django\db\backends\base\base.py", line 275, in ensure_connection
    self.connect()
  File "D:\PramLearn\.venv\Lib\site-packages\django\utils\asyncio.py", line 26, in inner
    return func(*args, **kwargs)
           ^^^^^^^^^^^^^^^^^^^^^
  File "D:\PramLearn\.venv\Lib\site-packages\django\db\backends\base\base.py", line 256, in connect
    self.connection = self.get_new_connection(conn_params)
                      ^^^^^^^^^^^^^^^^^^^^^^^^^^^^^^^^^^^^
  File "D:\PramLearn\.venv\Lib\site-packages\django\utils\asyncio.py", line 26, in inner
    return func(*args, **kwargs)
           ^^^^^^^^^^^^^^^^^^^^^
  File "D:\PramLearn\.venv\Lib\site-packages\django\db\backends\postgresql\base.py", line 277, in get_new_connection
    connection = self.Database.connect(**conn_params)
                 ^^^^^^^^^^^^^^^^^^^^^^^^^^^^^^^^^^^^
  File "D:\PramLearn\.venv\Lib\site-packages\psycopg2\__init__.py", line 121, in connect
    dsn = _ext.make_dsn(dsn, **kwargs)
          ^^^^^^^^^^^^^^^^^^^^^^^^^^^^
  File "D:\PramLearn\.venv\Lib\site-packages\psycopg2\extensions.py", line 167, in make_dsn
    parse_dsn(dsn)
psycopg2.ProgrammingError: invalid dsn: invalid connection option "charset"


The above exception was the direct cause of the following exception:

Traceback (most recent call last):
  File "D:\PramLearn\backendpramlearn\manage.py", line 22, in <module>
    main()
  File "D:\PramLearn\backendpramlearn\manage.py", line 18, in main
    execute_from_command_line(sys.argv)
  File "D:\PramLearn\.venv\Lib\site-packages\django\core\management\__init__.py", line 442, in execute_from_command_line
    utility.execute()
  File "D:\PramLearn\.venv\Lib\site-packages\django\core\management\__init__.py", line 436, in execute
    self.fetch_command(subcommand).run_from_argv(self.argv)
  File "D:\PramLearn\.venv\Lib\site-packages\django\core\management\base.py", line 413, in run_from_argv
    self.execute(*args, **cmd_options)
  File "D:\PramLearn\.venv\Lib\site-packages\django\core\management\base.py", line 459, in execute
    output = self.handle(*args, **options)
             ^^^^^^^^^^^^^^^^^^^^^^^^^^^^^
  File "D:\PramLearn\.venv\Lib\site-packages\django\core\management\commands\loaddata.py", line 101, in handle
    with transaction.atomic(using=self.using):
         ^^^^^^^^^^^^^^^^^^^^^^^^^^^^^^^^^^^^
  File "D:\PramLearn\.venv\Lib\site-packages\django\db\transaction.py", line 198, in __enter__
    if not connection.get_autocommit():
           ^^^^^^^^^^^^^^^^^^^^^^^^^^^
  File "D:\PramLearn\.venv\Lib\site-packages\django\db\backends\base\base.py", line 450, in get_autocommit
    self.ensure_connection()
  File "D:\PramLearn\.venv\Lib\site-packages\django\utils\asyncio.py", line 26, in inner
    return func(*args, **kwargs)
           ^^^^^^^^^^^^^^^^^^^^^
  File "D:\PramLearn\.venv\Lib\site-packages\django\db\backends\base\base.py", line 274, in ensure_connection
    with self.wrap_database_errors:
         ^^^^^^^^^^^^^^^^^^^^^^^^^
  File "D:\PramLearn\.venv\Lib\site-packages\django\db\utils.py", line 91, in __exit__
    raise dj_exc_value.with_traceback(traceback) from exc_value
  File "D:\PramLearn\.venv\Lib\site-packages\django\db\backends\base\base.py", line 275, in ensure_connection
    self.connect()
  File "D:\PramLearn\.venv\Lib\site-packages\django\utils\asyncio.py", line 26, in inner
    return func(*args, **kwargs)
           ^^^^^^^^^^^^^^^^^^^^^
  File "D:\PramLearn\.venv\Lib\site-packages\django\db\backends\base\base.py", line 256, in connect
    self.connection = self.get_new_connection(conn_params)
                      ^^^^^^^^^^^^^^^^^^^^^^^^^^^^^^^^^^^^
  File "D:\PramLearn\.venv\Lib\site-packages\django\utils\asyncio.py", line 26, in inner
    return func(*args, **kwargs)
           ^^^^^^^^^^^^^^^^^^^^^
  File "D:\PramLearn\.venv\Lib\site-packages\django\db\backends\postgresql\base.py", line 277, in get_new_connection
    connection = self.Database.connect(**conn_params)
                 ^^^^^^^^^^^^^^^^^^^^^^^^^^^^^^^^^^^^
  File "D:\PramLearn\.venv\Lib\site-packages\psycopg2\__init__.py", line 121, in connect
    dsn = _ext.make_dsn(dsn, **kwargs)
          ^^^^^^^^^^^^^^^^^^^^^^^^^^^^
  File "D:\PramLearn\.venv\Lib\site-packages\psycopg2\extensions.py", line 167, in make_dsn
    parse_dsn(dsn)
django.db.utils.ProgrammingError: invalid dsn: invalid connection option "charset"

✓ Seed data loaded successfully
Step 11: Generating ARCS CSV file...
✓ ARCS CSV generated successfully
Step 12: Creating superuser...
D:\PramLearn\.venv\Lib\site-packages\rest_framework_simplejwt\__init__.py:1: UserWarning: pkg_resources is deprecated as an API. See https://setuptools.pypa.io/en/latest/pkg_resources.html. The pkg_resources package is slated for removal as early as 2025-11-30. Refrain from using this package or pin to Setuptools<81.
  from pkg_resources import DistributionNotFound, get_distribution
Traceback (most recent call last):
  File "D:\PramLearn\.venv\Lib\site-packages\django\db\backends\base\base.py", line 275, in ensure_connection
    self.connect()
  File "D:\PramLearn\.venv\Lib\site-packages\django\utils\asyncio.py", line 26, in inner
    return func(*args, **kwargs)
           ^^^^^^^^^^^^^^^^^^^^^
  File "D:\PramLearn\.venv\Lib\site-packages\django\db\backends\base\base.py", line 256, in connect
    self.connection = self.get_new_connection(conn_params)
                      ^^^^^^^^^^^^^^^^^^^^^^^^^^^^^^^^^^^^
  File "D:\PramLearn\.venv\Lib\site-packages\django\utils\asyncio.py", line 26, in inner
    return func(*args, **kwargs)
           ^^^^^^^^^^^^^^^^^^^^^
  File "D:\PramLearn\.venv\Lib\site-packages\django\db\backends\postgresql\base.py", line 277, in get_new_connection
    connection = self.Database.connect(**conn_params)
                 ^^^^^^^^^^^^^^^^^^^^^^^^^^^^^^^^^^^^
  File "D:\PramLearn\.venv\Lib\site-packages\psycopg2\__init__.py", line 121, in connect
    dsn = _ext.make_dsn(dsn, **kwargs)
          ^^^^^^^^^^^^^^^^^^^^^^^^^^^^
  File "D:\PramLearn\.venv\Lib\site-packages\psycopg2\extensions.py", line 167, in make_dsn
    parse_dsn(dsn)
psycopg2.ProgrammingError: invalid dsn: invalid connection option "charset"


The above exception was the direct cause of the following exception:

Traceback (most recent call last):
  File "<string>", line 10, in <module>
  File "D:\PramLearn\.venv\Lib\site-packages\django\db\models\query.py", line 1288, in exists
    return self.query.has_results(using=self.db)
           ^^^^^^^^^^^^^^^^^^^^^^^^^^^^^^^^^^^^^
  File "D:\PramLearn\.venv\Lib\site-packages\django\db\models\sql\query.py", line 659, in has_results
    return compiler.has_results()
           ^^^^^^^^^^^^^^^^^^^^^^
  File "D:\PramLearn\.venv\Lib\site-packages\django\db\models\sql\compiler.py", line 1530, in has_results
    return bool(self.execute_sql(SINGLE))
                ^^^^^^^^^^^^^^^^^^^^^^^^
  File "D:\PramLearn\.venv\Lib\site-packages\django\db\models\sql\compiler.py", line 1560, in execute_sql
    cursor = self.connection.cursor()
             ^^^^^^^^^^^^^^^^^^^^^^^^
  File "D:\PramLearn\.venv\Lib\site-packages\django\utils\asyncio.py", line 26, in inner
    return func(*args, **kwargs)
           ^^^^^^^^^^^^^^^^^^^^^
  File "D:\PramLearn\.venv\Lib\site-packages\django\db\backends\base\base.py", line 316, in cursor
    return self._cursor()
           ^^^^^^^^^^^^^^
  File "D:\PramLearn\.venv\Lib\site-packages\django\db\backends\base\base.py", line 292, in _cursor
    self.ensure_connection()
  File "D:\PramLearn\.venv\Lib\site-packages\django\utils\asyncio.py", line 26, in inner
    return func(*args, **kwargs)
           ^^^^^^^^^^^^^^^^^^^^^
  File "D:\PramLearn\.venv\Lib\site-packages\django\db\backends\base\base.py", line 274, in ensure_connection
    with self.wrap_database_errors:
         ^^^^^^^^^^^^^^^^^^^^^^^^^
  File "D:\PramLearn\.venv\Lib\site-packages\django\db\utils.py", line 91, in __exit__
    raise dj_exc_value.with_traceback(traceback) from exc_value
  File "D:\PramLearn\.venv\Lib\site-packages\django\db\backends\base\base.py", line 275, in ensure_connection
    self.connect()
  File "D:\PramLearn\.venv\Lib\site-packages\django\utils\asyncio.py", line 26, in inner
    return func(*args, **kwargs)
           ^^^^^^^^^^^^^^^^^^^^^
  File "D:\PramLearn\.venv\Lib\site-packages\django\db\backends\base\base.py", line 256, in connect
    self.connection = self.get_new_connection(conn_params)
                      ^^^^^^^^^^^^^^^^^^^^^^^^^^^^^^^^^^^^
  File "D:\PramLearn\.venv\Lib\site-packages\django\utils\asyncio.py", line 26, in inner
    return func(*args, **kwargs)
           ^^^^^^^^^^^^^^^^^^^^^
  File "D:\PramLearn\.venv\Lib\site-packages\django\db\backends\postgresql\base.py", line 277, in get_new_connection
    connection = self.Database.connect(**conn_params)
                 ^^^^^^^^^^^^^^^^^^^^^^^^^^^^^^^^^^^^
  File "D:\PramLearn\.venv\Lib\site-packages\psycopg2\__init__.py", line 121, in connect
    dsn = _ext.make_dsn(dsn, **kwargs)
          ^^^^^^^^^^^^^^^^^^^^^^^^^^^^
  File "D:\PramLearn\.venv\Lib\site-packages\psycopg2\extensions.py", line 167, in make_dsn
    parse_dsn(dsn)
django.db.utils.ProgrammingError: invalid dsn: invalid connection option "charset"

===============================================
Reset and Seed Process Completed Successfully!
Mon, Jun  2, 2025  8:19:39 PM
===============================================
